Workbook

Sheet Senaryo Karsilastirma
A1: RasyoLog Finansal Model — 3 Senaryo Karsilastirma
A2: Toplanti: 2026-06-08 14:00 | Hazirlik: 2026-05-25 | Sahibi: Ozgur GUR
A4: Metrik | B4: Base | C4: Bull | D4: Bear
A5: Hedef Musteri (Ay 24) | B5: =Base!B5 | C5: =Bull!B5 | D5: =Bear!B5
A6: ARPU (EUR/ay) | B6: =Base!B6 | C6: =Bull!B6 | D6: =Bear!B6
A7: Aylik Churn | B7: =Base!B7 | C7: =Bull!B7 | D7: =Bear!B7
A8: CAC (EUR) | B8: =Base!B8 | C8: =Bull!B8 | D8: =Bear!B8
A9: Brut Marj | B9: =Base!B9 | C9: =Bull!B9 | D9: =Bear!B9
A10: --- SONUC METRIKLERI ---
A11: 2026 EOY ARR (EUR) | B11: =Base!B41 | C11: =Bull!B41 | D11: =Bear!B41
A12: 2027 EOY ARR (EUR) | B12: =Base!B42 | C12: =Bull!B42 | D12: =Bear!B42
A13: Toplam 24-Ay Gelir (EUR) | B13: =Base!B43 | C13: =Bull!B43 | D13: =Bear!B43
A14: Toplam OPEX (EUR) | B14: =Base!B44 | C14: =Bull!B44 | D14: =Bear!B44
A15: Toplam CAC Yatirimi (EUR) | B15: =Base!B45 | C15: =Bull!B45 | D15: =Bear!B45
A16: Toplam Brut Kar (EUR) | B16: =Base!B46 | C16: =Bull!B46 | D16: =Bear!B46
A17: Kumulatif EBITDA Ay 24 (EUR) | B17: =Base!B47 | C17: =Bull!B47 | D17: =Bear!B47
A18: Maksimum Cash Burn (EUR) | B18: =Base!B48 | C18: =Bull!B48 | D18: =Bear!B48
A19: Break-Even Ayi | B19: =Base!B49 | C19: =Bull!B49 | D19: =Bear!B49
A20: Cash-Positive Ayi | B20: =Base!B50 | C20: =Bull!B50 | D20: =Bear!B50
A22: Yorum Notlari
A23: • Base senaryo Fuat'in 5-12 mailindeki hedefe karsilik geliyor: 250 musteri x EUR500 = EUR1.5M ARR 2027 EOY.
A24: • Bull senaryo S-curve buyume (yatirimci-ready): EUR2.5M+ ARR potansiyeli, hizli launch + dusuk churn.
A25: • Bear senaryo: Adnan carve-out reddi + musteri transfer riski + yuksek CAC. EUR720K ARR — break-even disinda.
A26: • Tum senaryolarda OPEX EUR700K/yil combined sabit (Movetech + Rasyotek her biri EUR350K).
A27: • Brut marj senaryolara gore degisir: Base 80%, Bull 85% (volume discount tedarikci), Bear 75% (operasyonel verimsizlik).
A28: • Break-even Base'de ~ay 18-22 araliginda; Bull ay 14-16; Bear 24 ay icinde gerceklesmeyebilir.
A29: • 8 Haziran toplantisinda Erdem/Sedat'a Bull senaryoyu sun, ama Bear'i de masada tut (red-team olarak).

Sheet Base
A1: RasyoLog Finansal Model — Senaryo: Base
A2: Base: Linear ramp 0→250 müşteri, €500 ARPU, %5 churn, €1500 CAC
A4: Parametreler
A5: Hedef Müşteri (Ay 24) | B5: 250
A6: ARPU (€/ay/müşteri) | B6: 500
A7: Aylık Churn Oranı | B7: 0.05
A8: CAC (€/müşteri) | B8: 1500
A9: Brüt Marj (SaaS hosting + destek sonrası) | B9: 0.8
A10: OPEX Aylık (€) — sabit, €700K/yıl combined | B10: 58333.333
A11: Ramp Tipi | B11: linear
A13: Ay | B13: Aktif Müşteri (Ay Sonu) | C13: Churn'lu Müşteri | D13: Yeni Edinilen Müşteri | E13: Gelir (€) | F13: Kayıp MRR (Churn €) | G13: Brüt Kar (€) | H13: CAC Maliyeti (€) | I13: OPEX (€) | J13: EBITDA (€) | K13: Kümülatif Cash (€)
A14: 1 | B14: =ROUND($B$5*A14/24,0) | C14: 0 | D14: =B14+C14 | E14: =B14/2*$B$6 | F14: =C14*$B$6 | G14: =E14*$B$9 | H14: =D14*$B$8 | I14: =$B$10 | J14: =G14-H14-I14 | K14: =J14
A15: 2 | B15: =ROUND($B$5*A15/24,0) | C15: =ROUND(B14*$B$7,0) | D15: =MAX(B15-B14+C15,0) | E15: =(B14+B15)/2*$B$6 | F15: =C15*$B$6 | G15: =E15*$B$9 | H15: =D15*$B$8 | I15: =$B$10 | J15: =G15-H15-I15 | K15: =K14+J15
A16: 3 | B16: =ROUND($B$5*A16/24,0) | C16: =ROUND(B15*$B$7,0) | D16: =MAX(B16-B15+C16,0) | E16: =(B15+B16)/2*$B$6 | F16: =C16*$B$6 | G16: =E16*$B$9 | H16: =D16*$B$8 | I16: =$B$10 | J16: =G16-H16-I16 | K16: =K15+J16
A17: 4 | B17: =ROUND($B$5*A17/24,0) | C17: =ROUND(B16*$B$7,0) | D17: =MAX(B17-B16+C17,0) | E17: =(B16+B17)/2*$B$6 | F17: =C17*$B$6 | G17: =E17*$B$9 | H17: =D17*$B$8 | I17: =$B$10 | J17: =G17-H17-I17 | K17: =K16+J17
A18: 5 | B18: =ROUND($B$5*A18/24,0) | C18: =ROUND(B17*$B$7,0) | D18: =MAX(B18-B17+C18,0) | E18: =(B17+B18)/2*$B$6 | F18: =C18*$B$6 | G18: =E18*$B$9 | H18: =D18*$B$8 | I18: =$B$10 | J18: =G18-H18-I18 | K18: =K17+J18
A19: 6 | B19: =ROUND($B$5*A19/24,0) | C19: =ROUND(B18*$B$7,0) | D19: =MAX(B19-B18+C19,0) | E19: =(B18+B19)/2*$B$6 | F19: =C19*$B$6 | G19: =E19*$B$9 | H19: =D19*$B$8 | I19: =$B$10 | J19: =G19-H19-I19 | K19: =K18+J19
A20: 7 | B20: =ROUND($B$5*A20/24,0) | C20: =ROUND(B19*$B$7,0) | D20: =MAX(B20-B19+C20,0) | E20: =(B19+B20)/2*$B$6 | F20: =C20*$B$6 | G20: =E20*$B$9 | H20: =D20*$B$8 | I20: =$B$10 | J20: =G20-H20-I20 | K20: =K19+J20
A21: 8 | B21: =ROUND($B$5*A21/24,0) | C21: =ROUND(B20*$B$7,0) | D21: =MAX(B21-B20+C21,0) | E21: =(B20+B21)/2*$B$6 | F21: =C21*$B$6 | G21: =E21*$B$9 | H21: =D21*$B$8 | I21: =$B$10 | J21: =G21-H21-I21 | K21: =K20+J21
A22: 9 | B22: =ROUND($B$5*A22/24,0) | C22: =ROUND(B21*$B$7,0) | D22: =MAX(B22-B21+C22,0) | E22: =(B21+B22)/2*$B$6 | F22: =C22*$B$6 | G22: =E22*$B$9 | H22: =D22*$B$8 | I22: =$B$10 | J22: =G22-H22-I22 | K22: =K21+J22
A23: 10 | B23: =ROUND($B$5*A23/24,0) | C23: =ROUND(B22*$B$7,0) | D23: =MAX(B23-B22+C23,0) | E23: =(B22+B23)/2*$B$6 | F23: =C23*$B$6 | G23: =E23*$B$9 | H23: =D23*$B$8 | I23: =$B$10 | J23: =G23-H23-I23 | K23: =K22+J23
A24: 11 | B24: =ROUND($B$5*A24/24,0) | C24: =ROUND(B23*$B$7,0) | D24: =MAX(B24-B23+C24,0) | E24: =(B23+B24)/2*$B$6 | F24: =C24*$B$6 | G24: =E24*$B$9 | H24: =D24*$B$8 | I24: =$B$10 | J24: =G24-H24-I24 | K24: =K23+J24
A25: 12 | B25: =ROUND($B$5*A25/24,0) | C25: =ROUND(B24*$B$7,0) | D25: =MAX(B25-B24+C25,0) | E25: =(B24+B25)/2*$B$6 | F25: =C25*$B$6 | G25: =E25*$B$9 | H25: =D25*$B$8 | I25: =$B$10 | J25: =G25-H25-I25 | K25: =K24+J25
A26: 13 | B26: =ROUND($B$5*A26/24,0) | C26: =ROUND(B25*$B$7,0) | D26: =MAX(B26-B25+C26,0) | E26: =(B25+B26)/2*$B$6 | F26: =C26*$B$6 | G26: =E26*$B$9 | H26: =D26*$B$8 | I26: =$B$10 | J26: =G26-H26-I26 | K26: =K25+J26
... A37: 24 | B37: =ROUND($B$5*A37/24,0) | C37: =ROUND(B36*$B$7,0) | D37: =MAX(B37-B36+C37,0) | E37: =(B36+B37)/2*$B$6 | F37: =C37*$B$6 | G37: =E37*$B$9 | H37: =D37*$B$8 | I37: =$B$10 | J37: =G37-H37-I37 | K37: =K36+J37
A40: Özet Metrikler
A41: 2026 EOY ARR (Ay 12 × 12) (€) | B41: =B25*$B$6*12
A42: 2027 EOY ARR (Ay 24 × 12) (€) | B42: =B37*$B$6*12
A43: Toplam 24-Ay Gelir (€) | B43: =SUM(E14:E37)
A44: Toplam OPEX (€) | B44: =SUM(I14:I37)
A45: Toplam CAC Yatırımı (€) | B45: =SUM(H14:H37)
A46: Toplam Brüt Kar (€) | B46: =SUM(G14:G37)
A47: Kümülatif EBITDA Ay 24 (€) | B47: =K37
A48: Maksimum Cash Burn / Trough (€) | B48: =MIN(K14:K37)
A49: Break-Even Ayı (ilk pozitif EBITDA) | B49: =IFERROR(INDEX(A14:A37,MATCH(TRUE,INDEX(J14:J37>0,0),0)),"24 ay icinde yok")
A50: Cash-Positive Ayı (kümülatif cash > 0) | B50: =IFERROR(INDEX(A14:A37,MATCH(TRUE,INDEX(K14:K37>0,0),0)),"24 ay icinde yok")
A53: Notlar
A54: 1. Linear ramp: Aktif müşteri = Hedef × (Ay / 24). S-curve: sigmoid, ay 12'de inflection.
A55: 2. Gelir = Ortalama aktif müşteri (önceki ay + bu ay) / 2 × ARPU.
A56: 3. Yeni Edinilen = Net büyüme + Churn replacement (gross adds).
...

Sheet Bull
A1: RasyoLog Finansal Model — Senaryo: Bull
A2: Bull: S-curve 350 müşteri, €600 ARPU, %3 churn, €1200 CAC
A4: Parametreler
A5: Hedef Müşteri (Ay 24) | B5: 350
A6: ARPU (€/ay/müşteri) | B6: 600
A7: Aylık Churn Oranı | B7: 0.03
A8: CAC (€/müşteri) | B8: 1200
A9: Brüt Marj (SaaS hosting + destek sonrası) | B9: 0.85
A10: OPEX Aylık (€) — sabit, €700K/yıl combined | B10: 58333.333
A11: Ramp Tipi | B11: scurve
A13: Ay | B13: Aktif Müşteri (Ay Sonu) | C13: Churn'lu Müşteri | D13: Yeni Edinilen Müşteri | E13: Gelir (€) | F13: Kayıp MRR (Churn €) | G13: Brüt Kar (€) | H13: CAC Maliyeti (€) | I13: OPEX (€) | J13: EBITDA (€) | K13: Kümülatif Cash (€)
A14: 1 | B14: =ROUND($B$5/(1+EXP(-0.45*(A14-12))),0) | C14: 0 | D14: =B14+C14 | E14: =B14/2*$B$6 | F14: =C14*$B$6 | G14: =E14*$B$9 | H14: =D14*$B$8 | I14: =$B$10 | J14: =G14-H14-I14 | K14: =J14
A15: 2 | B15: =ROUND($B$5/(1+EXP(-0.45*(A15-12))),0) | C15: =ROUND(B14*$B$7,0) | D15: =MAX(B15-B14+C15,0) | E15: =(B14+B15)/2*$B$6 | F15: =C15*$B$6 | G15: =E15*$B$9 | H15: =D15*$B$8 | I15: =$B$10 | J15: =G15-H15-I15 | K15: =K14+J15
A16: 3 | B16: =ROUND($B$5/(1+EXP(-0.45*(A16-12))),0) | C16: =ROUND(B15*$B$7,0) | D16: =MAX(B16-B15+C16,0) | E16: =(B15+B16)/2*$B$6 | F16: =C16*$B$6 | G16: =E16*$B$9 | H16: =D16*$B$8 | I16: =$B$10 | J16: =G16-H16-I16 | K16: =K15+J16
A17: 4 | B17: =ROUND($B$5/(1+EXP(-0.45*(A17-12))),0) | C17: =ROUND(B16*$B$7,0) | D17: =MAX(B17-B16+C17,0) | E17: =(B16+B17)/2*$B$6 | F17: =C17*$B$6 | G17: =E17*$B$9 | H17: =D17*$B$8 | I17: =$B$10 | J17: =G17-H17-I17 | K17: =K16+J17
A18: 5 | B18: =ROUND($B$5/(1+EXP(-0.45*(A18-12))),0) | C18: =ROUND(B17*$B$7,0) | D18: =MAX(B18-B17+C18,0) | E18: =(B17+B18)/2*$B$6 | F18: =C18*$B$6 | G18: =E18*$B$9 | H18: =D18*$B$8 | I18: =$B$10 | J18: =G18-H18-I18 | K18: =K17+J18
A19: 6 | B19: =ROUND($B$5/(1+EXP(-0.45*(A19-12))),0) | C19: =ROUND(B18*$B$7,0) | D19: =MAX(B19-B18+C19,0) | E19: =(B18+B19)/2*$B$6 | F19: =C19*$B$6 | G19: =E19*$B$9 | H19: =D19*$B$8 | I19: =$B$10 | J19: =G19-H19-I19 | K19: =K18+J19
A20: 7 | B20: =ROUND($B$5/(1+EXP(-0.45*(A20-12))),0) | C20: =ROUND(B19*$B$7,0) | D20: =MAX(B20-B19+C20,0) | E20: =(B19+B20)/2*$B$6 | F20: =C20*$B$6 | G20: =E20*$B$9 | H20: =D20*$B$8 | I20: =$B$10 | J20: =G20-H20-I20 | K20: =K19+J20
A21: 8 | B21: =ROUND($B$5/(1+EXP(-0.45*(A21-12))),0) | C21: =ROUND(B20*$B$7,0) | D21: =MAX(B21-B20+C21,0) | E21: =(B20+B21)/2*$B$6 | F21: =C21*$B$6 | G21: =E21*$B$9 | H21: =D21*$B$8 | I21: =$B$10 | J21: =G21-H21-I21 | K21: =K20+J21
A22: 9 | B22: =ROUND($B$5/(1+EXP(-0.45*(A22-12))),0) | C22: =ROUND(B21*$B$7,0) | D22: =MAX(B22-B21+C22,0) | E22: =(B21+B22)/2*$B$6 | F22: =C22*$B$6 | G22: =E22*$B$9 | H22: =D22*$B$8 | I22: =$B$10 | J22: =G22-H22-I22 | K22: =K21+J22
A23: 10 | B23: =ROUND($B$5/(1+EXP(-0.45*(A23-12))),0) | C23: =ROUND(B22*$B$7,0) | D23: =MAX(B23-B22+C23,0) | E23: =(B22+B23)/2*$B$6 | F23: =C23*$B$6 | G23: =E23*$B$9 | H23: =D23*$B$8 | I23: =$B$10 | J23: =G23-H23-I23 | K23: =K22+J23
A24: 11 | B24: =ROUND($B$5/(1+EXP(-0.45*(A24-12))),0) | C24: =ROUND(B23*$B$7,0) | D24: =MAX(B24-B23+C24,0) | E24: =(B23+B24)/2*$B$6 | F24: =C24*$B$6 | G24: =E24*$B$9 | H24: =D24*$B$8 | I24: =$B$10 | J24: =G24-H24-I24 | K24: =K23+J24
A25: 12 | B25: =ROUND($B$5/(1+EXP(-0.45*(A25-12))),0) | C25: =ROUND(B24*$B$7,0) | D25: =MAX(B25-B24+C25,0) | E25: =(B24+B25)/2*$B$6 | F25: =C25*$B$6 | G25: =E25*$B$9 | H25: =D25*$B$8 | I25: =$B$10 | J25: =G25-H25-I25 | K25: =K24+J25
A26: 13 | B26: =ROUND($B$5/(1+EXP(-0.45*(A26-12))),0) | C26: =ROUND(B25*$B$7,0) | D26: =MAX(B26-B25+C26,0) | E26: =(B25+B26)/2*$B$6 | F26: =C26*$B$6 | G26: =E26*$B$9 | H26: =D26*$B$8 | I26: =$B$10 | J26: =G26-H26-I26 | K26: =K25+J26
... A37: 24 | B37: =ROUND($B$5/(1+EXP(-0.45*(A37-12))),0) | C37: =ROUND(B36*$B$7,0) | D37: =MAX(B37-B36+C37,0) | E37: =(B36+B37)/2*$B$6 | F37: =C37*$B$6 | G37: =E37*$B$9 | H37: =D37*$B$8 | I37: =$B$10 | J37: =G37-H37-I37 | K37: =K36+J37
A40: Özet Metrikler
A41: 2026 EOY ARR (Ay 12 × 12) (€) | B41: =B25*$B$6*12
A42: 2027 EOY ARR (Ay 24 × 12) (€) | B42: =B37*$B$6*12
A43: Toplam 24-Ay Gelir (€) | B43: =SUM(E14:E37)
A44: Toplam OPEX (€) | B44: =SUM(I14:I37)
A45: Toplam CAC Yatırımı (€) | B45: =SUM(H14:H37)
A46: Toplam Brüt Kar (€) | B46: =SUM(G14:G37)
A47: Kümülatif EBITDA Ay 24 (€) | B47: =K37
A48: Maksimum Cash Burn / Trough (€) | B48: =MIN(K14:K37)
A49: Break-Even Ayı (ilk pozitif EBITDA) | B49: =IFERROR(INDEX(A14:A37,MATCH(TRUE,INDEX(J14:J37>0,0),0)),"24 ay icinde yok")
A50: Cash-Positive Ayı (kümülatif cash > 0) | B50: =IFERROR(INDEX(A14:A37,MATCH(TRUE,INDEX(K14:K37>0,0),0)),"24 ay icinde yok")
A53: Notlar
A54: 1. Linear ramp: Aktif müşteri = Hedef × (Ay / 24). S-curve: sigmoid, ay 12'de inflection.
A55: 2. Gelir = Ortalama aktif müşteri (önceki ay + bu ay) / 2 × ARPU.
A56: 3. Yeni Edinilen = Net büyüme + Churn replacement (gross adds).
...

Sheet Bear
A1: RasyoLog Finansal Model — Senaryo: Bear
A2: Bear: Linear 150 müşteri, €400 ARPU, %8 churn, €2000 CAC
A4: Parametreler
A5: Hedef Müşteri (Ay 24) | B5: 150
A6: ARPU (€/ay/müşteri) | B6: 400
A7: Aylık Churn Oranı | B7: 0.08
A8: CAC (€/müşteri) | B8: 2000
A9: Brüt Marj (SaaS hosting + destek sonrası) | B9: 0.75
A10: OPEX Aylık (€) — sabit, €700K/yıl combined | B10: 58333.333
A11: Ramp Tipi | B11: linear
A13: Ay | B13: Aktif Müşteri (Ay Sonu) | C13: Churn'lu Müşteri | D13: Yeni Edinilen Müşteri | E13: Gelir (€) | F13: Kayıp MRR (Churn €) | G13: Brüt Kar (€) | H13: CAC Maliyeti (€) | I13: OPEX (€) | J13: EBITDA (€) | K13: Kümülatif Cash (€)
A14: 1 | B14: =ROUND($B$5*A14/24,0) | C14: 0 | D14: =B14+C14 | E14: =B14/2*$B$6 | F14: =C14*$B$6 | G14: =E14*$B$9 | H14: =D14*$B$8 | I14: =$B$10 | J14: =G14-H14-I14 | K14: =J14
A15: 2 | B15: =ROUND($B$5*A15/24,0) | C15: =ROUND(B14*$B$7,0) | D15: =MAX(B15-B14+C15,0) | E15: =(B14+B15)/2*$B$6 | F15: =C15*$B$6 | G15: =E15*$B$9 | H15: =D15*$B$8 | I15: =$B$10 | J15: =G15-H15-I15 | K15: =K14+J15
A16: 3 | B16: =ROUND($B$5*A16/24,0) | C16: =ROUND(B15*$B$7,0) | D16: =MAX(B16-B15+C16,0) | E16: =(B15+B16)/2*$B$6 | F16: =C16*$B$6 | G16: =E16*$B$9 | H16: =D16*$B$8 | I16: =$B$10 | J16: =G16-H16-I16 | K16: =K15+J16
A17: 4 | B17: =ROUND($B$5*A17/24,0) | C17: =ROUND(B16*$B$7,0) | D17: =MAX(B17-B16+C17,0) | E17: =(B16+B17)/2*$B$6 | F17: =C17*$B$6 | G17: =E17*$B$9 | H17: =D17*$B$8 | I17: =$B$10 | J17: =G17-H17-I17 | K17: =K16+J17
A18: 5 | B18: =ROUND($B$5*A18/24,0) | C18: =ROUND(B17*$B$7,0) | D18: =MAX(B18-B17+C18,0) | E18: =(B17+B18)/2*$B$6 | F18: =C18*$B$6 | G18: =E18*$B$9 | H18: =D18*$B$8 | I18: =$B$10 | J18: =G18-H18-I18 | K18: =K17+J18
A19: 6 | B19: =ROUND($B$5*A19/24,0) | C19: =ROUND(B18*$B$7,0) | D19: =MAX(B19-B18+C19,0) | E19: =(B18+B19)/2*$B$6 | F19: =C19*$B$6 | G19: =E19*$B$9 | H19: =D19*$B$8 | I19: =$B$10 | J19: =G19-H19-I19 | K19: =K18+J19
A20: 7 | B20: =ROUND($B$5*A20/24,0) | C20: =ROUND(B19*$B$7,0) | D20: =MAX(B20-B19+C20,0) | E20: =(B19+B20)/2*$B$6 | F20: =C20*$B$6 | G20: =E20*$B$9 | H20: =D20*$B$8 | I20: =$B$10 | J20: =G20-H20-I20 | K20: =K19+J20
A21: 8 | B21: =ROUND($B$5*A21/24,0) | C21: =ROUND(B20*$B$7,0) | D21: =MAX(B21-B20+C21,0) | E21: =(B20+B21)/2*$B$6 | F21: =C21*$B$6 | G21: =E21*$B$9 | H21: =D21*$B$8 | I21: =$B$10 | J21: =G21-H21-I21 | K21: =K20+J21
A22: 9 | B22: =ROUND($B$5*A22/24,0) | C22: =ROUND(B21*$B$7,0) | D22: =MAX(B22-B21+C22,0) | E22: =(B21+B22)/2*$B$6 | F22: =C22*$B$6 | G22: =E22*$B$9 | H22: =D22*$B$8 | I22: =$B$10 | J22: =G22-H22-I22 | K22: =K21+J22
A23: 10 | B23: =ROUND($B$5*A23/24,0) | C23: =ROUND(B22*$B$7,0) | D23: =MAX(B23-B22+C23,0) | E23: =(B22+B23)/2*$B$6 | F23: =C23*$B$6 | G23: =E23*$B$9 | H23: =D23*$B$8 | I23: =$B$10 | J23: =G23-H23-I23 | K23: =K22+J23
A24: 11 | B24: =ROUND($B$5*A24/24,0) | C24: =ROUND(B23*$B$7,0) | D24: =MAX(B24-B23+C24,0) | E24: =(B23+B24)/2*$B$6 | F24: =C24*$B$6 | G24: =E24*$B$9 | H24: =D24*$B$8 | I24: =$B$10 | J24: =G24-H24-I24 | K24: =K23+J24
A25: 12 | B25: =ROUND($B$5*A25/24,0) | C25: =ROUND(B24*$B$7,0) | D25: =MAX(B25-B24+C25,0) | E25: =(B24+B25)/2*$B$6 | F25: =C25*$B$6 | G25: =E25*$B$9 | H25: =D25*$B$8 | I25: =$B$10 | J25: =G25-H25-I25 | K25: =K24+J25
A26: 13 | B26: =ROUND($B$5*A26/24,0) | C26: =ROUND(B25*$B$7,0) | D26: =MAX(B26-B25+C26,0) | E26: =(B25+B26)/2*$B$6 | F26: =C26*$B$6 | G26: =E26*$B$9 | H26: =D26*$B$8 | I26: =$B$10 | J26: =G26-H26-I26 | K26: =K25+J26
... A37: 24 | B37: =ROUND($B$5*A37/24,0) | C37: =ROUND(B36*$B$7,0) | D37: =MAX(B37-B36+C37,0) | E37: =(B36+B37)/2*$B$6 | F37: =C37*$B$6 | G37: =E37*$B$9 | H37: =D37*$B$8 | I37: =$B$10 | J37: =G37-H37-I37 | K37: =K36+J37
A40: Özet Metrikler
A41: 2026 EOY ARR (Ay 12 × 12) (€) | B41: =B25*$B$6*12
A42: 2027 EOY ARR (Ay 24 × 12) (€) | B42: =B37*$B$6*12
A43: Toplam 24-Ay Gelir (€) | B43: =SUM(E14:E37)
A44: Toplam OPEX (€) | B44: =SUM(I14:I37)
A45: Toplam CAC Yatırımı (€) | B45: =SUM(H14:H37)
A46: Toplam Brüt Kar (€) | B46: =SUM(G14:G37)
A47: Kümülatif EBITDA Ay 24 (€) | B47: =K37
A48: Maksimum Cash Burn / Trough (€) | B48: =MIN(K14:K37)
A49: Break-Even Ayı (ilk pozitif EBITDA) | B49: =IFERROR(INDEX(A14:A37,MATCH(TRUE,INDEX(J14:J37>0,0),0)),"24 ay icinde yok")
A50: Cash-Positive Ayı (kümülatif cash > 0) | B50: =IFERROR(INDEX(A14:A37,MATCH(TRUE,INDEX(K14:K37>0,0),0)),"24 ay icinde yok")
A53: Notlar
A54: 1. Linear ramp: Aktif müşteri = Hedef × (Ay / 24). S-curve: sigmoid, ay 12'de inflection.
A55: 2. Gelir = Ortalama aktif müşteri (önceki ay + bu ay) / 2 × ARPU.
A56: 3. Yeni Edinilen = Net büyüme + Churn replacement (gross adds).
...
